#usda 1.0
(
    customLayerData = {
        dictionary cameraSettings = {
            dictionary Front = {
                double3 position = (5, 0, 0)
                double radius = 5
            }
            dictionary Perspective = {
                double3 position = (0.05162871469388322, 0.04657976740605083, 0.01444098192697504)
                double3 target = (-0.0011512242011863308, -0.019972843794894286, 0.01615322799293502)
            }
            dictionary Right = {
                double3 position = (0, -5, 0)
                double radius = 5
            }
            dictionary Top = {
                double3 position = (0, 0, 5)
                double radius = 5
            }
            string boundCamera = "/OmniverseKit_Persp"
        }
        dictionary omni_layer = {
            string authoring_layer = "./official_hex_sim_no_rack_and_pinion.usda"
        }
        dictionary renderSettings = {
        }
    }
    defaultPrim = "World"
    endTimeCode = 1000000
    metersPerUnit = 1
    startTimeCode = 0
    timeCodesPerSecond = 60
    upAxis = "Z"
)

def Xform "World"
{
    def Xform "GroundPlane"
    {
        quatf xformOp:orient = (1, 0, 0, 0)
        float3 xformOp:scale = (1, 1, 1)
        double3 xformOp:translate = (0, 0, 0)
        uniform token[] xformOpOrder = ["xformOp:translate", "xformOp:orient", "xformOp:scale"]

        def Mesh "CollisionMesh"
        {
            uniform bool doubleSided = 0
            int[] faceVertexCounts = [4]
            int[] faceVertexIndices = [0, 1, 2, 3]
            normal3f[] normals = [(0, 0, 1), (0, 0, 1), (0, 0, 1), (0, 0, 1)]
            point3f[] points = [(-25, -25, 0), (25, -25, 0), (25, 25, 0), (-25, 25, 0)]
            color3f[] primvars:displayColor = [(0.5, 0.5, 0.5)]
            texCoord2f[] primvars:st = [(0, 0), (1, 0), (1, 1), (0, 1)] (
                interpolation = "varying"
            )
        }

        def Plane "CollisionPlane" (
            prepend apiSchemas = ["PhysicsCollisionAPI"]
        )
        {
            uniform token axis = "Z"
            uniform token purpose = "guide"
        }
    }

    def PhysicsScene "PhysicsScene" (
        prepend apiSchemas = ["PhysxSceneAPI"]
    )
    {
    }

    def Xform "NutBoltAssembly" (
        prepend apiSchemas = ["NewtonArticulationRootAPI"]
    )
    {
        bool newton:selfCollisionEnabled = 0

        def Xform "Bolt" (
            prepend apiSchemas = ["PhysicsRigidBodyAPI", "PhysxRigidBodyAPI"]
            references = @./hex_bolt/bolt.usd@
        )
        {
            bool physics:kinematicEnabled = 0
            bool physics:rigidBodyEnabled = 1
            quatd xformOp:orient = (1, 0, 0, 0)
            double3 xformOp:scale = (0.001, 0.001, 0.001)
            double3 xformOp:translate = (0, 0, 0)
            uniform token[] xformOpOrder = ["xformOp:translate", "xformOp:orient", "xformOp:scale"]

            def PhysicsRevoluteJoint "RevoluteJoint" (
                prepend apiSchemas = ["PhysicsDriveAPI:angular"]
            )
            {
                float drive:angular:physics:damping = 100000
                float drive:angular:physics:stiffness = 0
                float drive:angular:physics:targetVelocity = 250
                uniform token drive:angular:physics:type = "force"
                uniform token physics:axis = "Z"
                rel physics:body1 = </World/NutBoltAssembly/Bolt>
                float physics:breakForce = 3.4028235e38
                float physics:breakTorque = 3.4028235e38
                point3f physics:localPos0 = (0, 0, 0)
                point3f physics:localPos1 = (0, 0, 0)
                quatf physics:localRot0 = (1, 0, 0, 0)
                quatf physics:localRot1 = (1, 0, 0, 0)
            }

            over "PolyShape" (
                prepend apiSchemas = ["PhysicsCollisionAPI", "PhysxCollisionAPI", "PhysxConvexHullCollisionAPI", "PhysicsMeshCollisionAPI"]
            )
            {
                uniform token physics:approximation = "convexHull"
                bool physics:collisionEnabled = 1
            }
        }

        def Xform "Nut" (
            prepend apiSchemas = ["PhysicsRigidBodyAPI", "PhysxRigidBodyAPI"]
            references = @./hex_bolt/nut.usd@
        )
        {
            bool physics:kinematicEnabled = 0
            bool physics:rigidBodyEnabled = 1
            quatd xformOp:orient = (1, 0, 0, 0)
            double3 xformOp:scale = (0.001, 0.001, 0.001)
            double3 xformOp:translate = (0, 0, 0.005304437984352175)
            uniform token[] xformOpOrder = ["xformOp:translate", "xformOp:orient", "xformOp:scale"]

            def PhysicsPrismaticJoint "PrismaticJoint" (
                prepend apiSchemas = ["NewtonMimicAPI"]
            )
            {
                float newton:mimicCoef0 = 0
                float newton:mimicCoef1 = 0.0000025198412
                bool newton:mimicEnabled = 1
                rel newton:mimicJoint = </World/NutBoltAssembly/Bolt/RevoluteJoint>
                uniform token physics:axis = "Z"
                rel physics:body0 = </World/NutBoltAssembly/Bolt>
                rel physics:body1 = </World/NutBoltAssembly/Nut>
                float physics:breakForce = 3.4028235e38
                float physics:breakTorque = 3.4028235e38
                point3f physics:localPos0 = (0, 0, 0.005304438)
                point3f physics:localPos1 = (0, 0, 0)
                quatf physics:localRot0 = (1, 0, 0, 0)
                quatf physics:localRot1 = (1, 0, 0, 0)
                float physics:lowerLimit = 0.0053
                float physics:upperLimit = 0.02
            }

            over "PolyShape" (
                prepend apiSchemas = ["PhysicsCollisionAPI", "PhysxCollisionAPI", "PhysxConvexHullCollisionAPI", "PhysicsMeshCollisionAPI"]
            )
            {
                uniform token physics:approximation = "convexHull"
                bool physics:collisionEnabled = 1
            }
        }
    }
}

def "Render" (
    hide_in_stage_window = true
    no_delete = true
)
{
    def "OmniverseKit"
    {
        def "HydraTextures" (
            hide_in_stage_window = true
            no_delete = true
        )
        {
            def RenderProduct "omni_kit_widget_viewport_ViewportTexture_0" (
                prepend apiSchemas = ["OmniRtxSettingsCommonAdvancedAPI_1", "OmniRtxSettingsRtAdvancedAPI_1", "OmniRtxSettingsPtAdvancedAPI_1", "OmniRtxPostColorGradingAPI_1", "OmniRtxPostChromaticAberrationAPI_1", "OmniRtxPostBloomPhysicalAPI_1", "OmniRtxPostMatteObjectAPI_1", "OmniRtxPostCompositingAPI_1", "OmniRtxPostDofAPI_1", "OmniRtxPostMotionBlurAPI_1", "OmniRtxPostTvNoiseAPI_1", "OmniRtxPostTonemapIrayReinhardAPI_1", "OmniRtxPostDebugSettingsAPI_1", "OmniRtxDebugSettingsAPI_1"]
                hide_in_stage_window = true
                no_delete = true
            )
            {
                rel camera = </OmniverseKit_Persp>
                token omni:rtx:background:source:texture:textureMode = "repeatMirrored"
                token omni:rtx:background:source:type = "domeLight"
                bool omni:rtx:dlss:frameGeneration = 0
                bool omni:rtx:material:db:nonVisualMaterialCSV:enabled = 0
                bool omni:rtx:material:db:syncLoads = 1
                token omni:rtx:post:dlss:execMode = "performance"
                bool omni:rtx:post:registeredCompositing:invertColorCorrection = 1
                bool omni:rtx:post:registeredCompositing:invertToneMap = 1
                bool omni:rtx:pt:lightcache:cached:dontResolveConflicts = 1
                int omni:rtx:pt:maxSamplesPerLaunch = 2073600
                int omni:rtx:pt:mgpu:maxPixelsPerRegionExponent = 12
                color3f omni:rtx:rt:ambientLight:color = (0.1, 0.1, 0.1)
                bool omni:rtx:rt:demoire = 0
                bool omni:rtx:rt:ecoMode:enabled
                bool omni:rtx:rt:lightcache:spatialCache:dontResolveConflicts = 1
                bool omni:rtx:scene:hydra:materialSyncLoads = 1
                bool omni:rtx:scene:hydra:mdlMaterialWarmup = 1
                uint omni:rtx:viewTile:limit = 4294967295
                rel orderedVars = </Render/Vars/LdrColor>
                custom bool overrideClipRange = 0
                uniform int2 resolution = (1285, 687)
            }
        }
    }

    def RenderSettings "OmniverseGlobalRenderSettings" (
        prepend apiSchemas = ["OmniRtxSettingsGlobalRtAdvancedAPI_1", "OmniRtxSettingsGlobalPtAdvancedAPI_1"]
        no_delete = true
    )
    {
        rel products = </Render/OmniverseKit/HydraTextures/omni_kit_widget_viewport_ViewportTexture_0>
    }

    def "Vars"
    {
        def RenderVar "LdrColor" (
            hide_in_stage_window = true
            no_delete = true
        )
        {
            uniform string sourceName = "LdrColor"
        }
    }
}

