#usda 1.0
(
    customLayerData = {
        dictionary cameraSettings = {
            dictionary Front = {
                double3 position = (5, 0, 0)
                double radius = 5
            }
            dictionary Perspective = {
                double3 position = (0.017295585325391164, 0.07376733370715478, 0.014028798324086406)
                double3 target = (-0.025646213156667586, 0.0060831461159781275, 0.01692829433398063)
            }
            dictionary Right = {
                double3 position = (0, -5, 0)
                double radius = 5
            }
            dictionary Top = {
                double3 position = (0, 0, 5)
                double radius = 5
            }
            string boundCamera = "/OmniverseKit_Persp"
        }
        dictionary omni_layer = {
            string authoring_layer = "./static_bolt_spinning_nut.usda"
        }
        dictionary renderSettings = {
        }
    }
    defaultPrim = "World"
    endTimeCode = 1000000
    metersPerUnit = 1
    startTimeCode = 0
    timeCodesPerSecond = 60
    upAxis = "Z"
)

def Xform "World"
{
    def PhysicsScene "PhysicsScene" (
        prepend apiSchemas = ["PhysxSceneAPI"]
    )
    {
    }

    def Xform "NutBoltAssembly" (
        prepend apiSchemas = ["PhysicsArticulationRootAPI", "PhysxArticulationAPI"]
    )
    {
        bool physxArticulation:enabledSelfCollisions = 0

        def Xform "Bolt" (
            prepend apiSchemas = ["PhysicsRigidBodyAPI", "PhysxRigidBodyAPI"]
            references = @./hex_bolt/bolt.usd@
        )
        {
            bool physics:kinematicEnabled = 0
            bool physics:rigidBodyEnabled = 1
            quatd xformOp:orient = (1, 0, 0, 0)
            double3 xformOp:scale = (0.001, 0.001, 0.001)
            double3 xformOp:translate = (0, 0, 0)
            uniform token[] xformOpOrder = ["xformOp:translate", "xformOp:orient", "xformOp:scale"]

            def PhysicsFixedJoint "BoltFixedJoint"
            {
                rel physics:body1 = </World/NutBoltAssembly/Bolt>
            }

            over "PolyShape" (
                prepend apiSchemas = ["PhysicsCollisionAPI", "PhysxCollisionAPI", "PhysxConvexHullCollisionAPI", "PhysicsMeshCollisionAPI"]
            )
            {
                uniform token physics:approximation = "convexHull"
                bool physics:collisionEnabled = 1
            }
        }

        def Xform "NutSlide" (
            prepend apiSchemas = ["PhysicsRigidBodyAPI", "PhysxRigidBodyAPI", "PhysicsMassAPI"]
        )
        {
            point3f physics:centerOfMass = (0, 0, 0)
            float3 physics:diagonalInertia = (1e-8, 1e-8, 1e-8)
            bool physics:kinematicEnabled = 0
            float physics:mass = 0.1
            quatf physics:principalAxes = (1, 0, 0, 0)
            bool physics:rigidBodyEnabled = 1
            quatd xformOp:orient = (1, 0, 0, 0)
            double3 xformOp:scale = (1, 1, 1)
            double3 xformOp:translate = (0, 0, 0.005304437984352175)
            uniform token[] xformOpOrder = ["xformOp:translate", "xformOp:orient", "xformOp:scale"]

            def Cube "Shape" (
                prepend apiSchemas = ["PhysicsCollisionAPI"]
            )
            {
                color3f[] primvars:displayColor = [(0.5, 0.5, 0.5)]
                double size = 1
                token visibility = "invisible"
                float3 xformOp:scale = (0.002, 0.002, 0.002)
                uniform token[] xformOpOrder = ["xformOp:scale"]
            }

            def PhysicsPrismaticJoint "NutSlidePrismatic" (
                prepend apiSchemas = ["PhysxJointAPI", "PhysicsDriveAPI:linear"]
            )
            {
                float drive:linear:physics:damping = 100000
                float drive:linear:physics:stiffness = 0
                float drive:linear:physics:targetVelocity = -0.00063
                uniform token drive:linear:physics:type = "force"
                uniform token physics:axis = "Z"
                rel physics:body0 = </World/NutBoltAssembly/Bolt>
                rel physics:body1 = </World/NutBoltAssembly/NutSlide>
                point3f physics:localPos0 = (0, 0, 0.005304438)
                point3f physics:localPos1 = (0, 0, 0)
                quatf physics:localRot0 = (1, 0, 0, 0)
                quatf physics:localRot1 = (1, 0, 0, 0)
                float physics:lowerLimit = 0.0053
                float physics:upperLimit = 0.02
            }
        }

        def Xform "Nut" (
            prepend apiSchemas = ["PhysicsRigidBodyAPI", "PhysxRigidBodyAPI"]
            references = @./hex_bolt/nut.usd@
        )
        {
            bool physics:kinematicEnabled = 0
            bool physics:rigidBodyEnabled = 1
            quatd xformOp:orient = (1, 0, 0, 0)
            double3 xformOp:scale = (0.001, 0.001, 0.001)
            double3 xformOp:translate = (0, 0, 0.005304437984352175)
            uniform token[] xformOpOrder = ["xformOp:translate", "xformOp:orient", "xformOp:scale"]

            over "PolyShape" (
                prepend apiSchemas = ["PhysicsCollisionAPI", "PhysxCollisionAPI", "PhysxConvexHullCollisionAPI", "PhysicsMeshCollisionAPI"]
            )
            {
                uniform token physics:approximation = "convexHull"
                bool physics:collisionEnabled = 1
            }

            def PhysicsRevoluteJoint "NutRevolute" (
                prepend apiSchemas = ["PhysxJointAPI", "PhysxMimicJointAPI:rotZ"]
            )
            {
                uniform token physics:axis = "Z"
                rel physics:body0 = </World/NutBoltAssembly/NutSlide>
                rel physics:body1 = </World/NutBoltAssembly/Nut>
                point3f physics:localPos0 = (0, 0, 0)
                point3f physics:localPos1 = (0, 0, 0)
                quatf physics:localRot0 = (1, 0, 0, 0)
                quatf physics:localRot1 = (1, 0, 0, 0)
                float physics:lowerLimit = -1000000
                float physics:upperLimit = 1000000
                float physxMimicJoint:rotZ:dampingRatio = 0
                float physxMimicJoint:rotZ:gearing = -396850.4
                float physxMimicJoint:rotZ:naturalFrequency = 0
                float physxMimicJoint:rotZ:offset = 0
                rel physxMimicJoint:rotZ:referenceJoint = </World/NutBoltAssembly/NutSlide/NutSlidePrismatic>
            }
        }
    }
}

def "Render" (
    hide_in_stage_window = true
    no_delete = true
)
{
    def "OmniverseKit"
    {
        def "HydraTextures" (
            hide_in_stage_window = true
            no_delete = true
        )
        {
            def RenderProduct "omni_kit_widget_viewport_ViewportTexture_0" (
                prepend apiSchemas = ["OmniRtxSettingsCommonAdvancedAPI_1", "OmniRtxSettingsRtAdvancedAPI_1", "OmniRtxSettingsPtAdvancedAPI_1", "OmniRtxPostColorGradingAPI_1", "OmniRtxPostChromaticAberrationAPI_1", "OmniRtxPostBloomPhysicalAPI_1", "OmniRtxPostMatteObjectAPI_1", "OmniRtxPostCompositingAPI_1", "OmniRtxPostDofAPI_1", "OmniRtxPostMotionBlurAPI_1", "OmniRtxPostTvNoiseAPI_1", "OmniRtxPostTonemapIrayReinhardAPI_1", "OmniRtxPostDebugSettingsAPI_1", "OmniRtxDebugSettingsAPI_1"]
                hide_in_stage_window = true
                no_delete = true
            )
            {
                rel camera = </OmniverseKit_Persp>
                token omni:rtx:background:source:texture:textureMode = "repeatMirrored"
                token omni:rtx:background:source:type = "domeLight"
                bool omni:rtx:dlss:frameGeneration = 0
                bool omni:rtx:material:db:nonVisualMaterialCSV:enabled = 0
                bool omni:rtx:material:db:syncLoads = 1
                token omni:rtx:post:dlss:execMode = "performance"
                bool omni:rtx:post:registeredCompositing:invertColorCorrection = 1
                bool omni:rtx:post:registeredCompositing:invertToneMap = 1
                bool omni:rtx:pt:lightcache:cached:dontResolveConflicts = 1
                int omni:rtx:pt:maxSamplesPerLaunch = 2073600
                int omni:rtx:pt:mgpu:maxPixelsPerRegionExponent = 12
                color3f omni:rtx:rt:ambientLight:color = (0.1, 0.1, 0.1)
                bool omni:rtx:rt:demoire = 0
                bool omni:rtx:rt:ecoMode:enabled
                bool omni:rtx:rt:lightcache:spatialCache:dontResolveConflicts = 1
                bool omni:rtx:scene:hydra:materialSyncLoads = 1
                bool omni:rtx:scene:hydra:mdlMaterialWarmup = 1
                uint omni:rtx:viewTile:limit = 4294967295
                rel orderedVars = </Render/Vars/LdrColor>
                custom bool overrideClipRange = 0
                uniform int2 resolution = (1285, 687)
            }
        }
    }

    def RenderSettings "OmniverseGlobalRenderSettings" (
        prepend apiSchemas = ["OmniRtxSettingsGlobalRtAdvancedAPI_1", "OmniRtxSettingsGlobalPtAdvancedAPI_1"]
        no_delete = true
    )
    {
        rel products = </Render/OmniverseKit/HydraTextures/omni_kit_widget_viewport_ViewportTexture_0>
    }

    def "Vars"
    {
        def RenderVar "LdrColor" (
            hide_in_stage_window = true
            no_delete = true
        )
        {
            uniform string sourceName = "LdrColor"
        }
    }
}

